<?xml version="1.0"?>
<robot name="screwdriver">
  <link name="screwdriver_base_link">
    <inertial>
      <mass value="1"/>
      <inertia ixx="1" iyy="1" izz="1" ixy="0" ixz="0" iyz="0"/>
    </inertial>
  </link>
  <link name="screwdriver_ee_link">
    <inertial>
      <mass value="1"/>
      <inertia ixx="1" iyy="1" izz="1" ixy="0" ixz="0" iyz="0"/>
    </inertial>
  </link>
  <joint name="screwdriver_joint" type="revolute">
    <parent link="screwdriver_base_link"/>
    <child link="screwdriver_ee_link"/>
  </joint>
  <transmission name="screwdriver_joint_trans">
    <type>transmission_interface/SimpleTransmission</type>
    <joint name="screwdriver_joint">
      <hardwareInterface>hardware_interface/EffortJointInterface</hardwareInterface>
    </joint>
    <actuator name="screwdriver_actuator">
      <mechanicalReduction>22</mechanicalReduction>
    </actuator>
  </transmission>
</robot>
